Workbook

Sheet README
A1: Luganda evaluation items: draft for native-speaker validation
A3: Claude wrote all items in this workbook. Claude is not a native speaker, so the items can contain errors.
A4: The evaluation notebooks use only the rows with STATUS = OK or FIXED.
A6: How to validate
A7: 1. Read each row. Edit only the yellow columns.
A8: 2. Set STATUS: OK = the row is correct as written. FIXED = you wrote a correction. DROP = do not use the row.
A9: 3. For FIXED: write the corrected text in the fixed_* columns. Leave a fixed_* column empty if that part is correct.
A10: 4. For minimal pairs: the correct and the wrong sentence must differ in ONE morpheme only. The wrong sentence must be ungrammatical.
A11: 5. Use validator_note for any comment (for example, a dialect form, or a second correct reading).
A12: 6. Do not change the id column. Do not rename the sheets or the column headers.
A14: Columns
A15: my_confidence: how sure Claude is about the Luganda (high / medium / low). Check the low and medium rows first.
... A23: progress: counts of STATUS for each sheet and each error type (formulas, updated automatically).

Sheet minimal_pairs
A1: id | B1: error_type | C1: correct | D1: wrong | E1: english | F1: changed_morpheme | G1: note | H1: my_confidence | I1: STATUS | J1: fixed_correct | K1: fixed_wrong | L1: validator_note
A2: NC-001 | B2: noun_class_agreement | C2: Ekitabo ekinene kiri ku mmeeza. | D2: Ekitabo ennene kiri ku mmeeza. | E2: The big book is on the table. | F2: eki- → en- (cl7 → cl9 adjective) | H2: high | I2: TODO
A3: NC-002 | B3: noun_class_agreement | C3: Ebitabo ebinene biri ku mmeeza. | D3: Ebitabo amanene biri ku mmeeza. | E3: The big books are on the table. | F3: ebi- → ama- (cl8 → cl6) | H3: high | I3: TODO
A4: NC-003 | B4: noun_class_agreement | C4: Omusajja omunene ali mu nnyumba. | D4: Omusajja ekinene ali mu nnyumba. | E4: The big man is in the house. | F4: omu- → eki- (cl1 → cl7) | H4: high | I4: TODO
A5: NC-004 | B5: noun_class_agreement | C5: Abasajja abanene bali mu nnyumba. | D5: Abasajja omunene bali mu nnyumba. | E5: The big men are in the house. | F5: aba- → omu- (cl2 → cl1) | H5: high | I5: TODO
A6: NC-005 | B6: noun_class_agreement | C6: Omuti omunene guli mu nnimiro. | D6: Omuti ekinene guli mu nnimiro. | E6: The big tree is in the garden. | F6: omu- → eki- (cl3 → cl7) | H6: high | I6: TODO
A7: NC-006 | B7: noun_class_agreement | C7: Emiti eminene giri mu nnimiro. | D7: Emiti ebinene giri mu nnimiro. | E7: The big trees are in the garden. | F7: emi- → ebi- (cl4 → cl8) | H7: high | I7: TODO
A8: NC-007 | B8: noun_class_agreement | C8: Ennyumba ennene eri ku lusozi. | D8: Ennyumba ekinene eri ku lusozi. | E8: The big house is on the hill. | F8: en- → eki- (cl9 → cl7) | H8: high | I8: TODO
A9: NC-008 | B9: noun_class_agreement | C9: Ejjinja eddene liri ku kkubo. | D9: Ejjinja ennene liri ku kkubo. | E9: The big stone is on the road. | F9: eri- (eddene) → en- (cl5 → cl9) | G9: Check the cl5 form eddene. | H9: medium | I9: TODO
A10: NC-009 | B10: noun_class_agreement | C10: Amayinja amanene gali ku kkubo. | D10: Amayinja ebinene gali ku kkubo. | E10: The big stones are on the road. | F10: ama- → ebi- (cl6 → cl8) | H10: high | I10: TODO
A11: NC-010 | B11: noun_class_agreement | C11: Olutindo olunene luli ku mugga. | D11: Olutindo ekinene luli ku mugga. | E11: The big bridge is on the river. | F11: olu- → eki- (cl11 → cl7) | H11: high | I11: TODO
A12: NC-011 | B12: noun_class_agreement | C12: Akambe akatono kali ku mmeeza. | D12: Akambe ekitono kali ku mmeeza. | E12: The small knife is on the table. | F12: aka- → eki- (cl12 → cl7) | H12: high | I12: TODO
A13: NC-012 | B13: noun_class_agreement | C13: Omwana omulungi ali ku ssomero. | D13: Omwana ekirungi ali ku ssomero. | E13: The good child is at school. | F13: omu- → eki- (cl1 → cl7) | H13: high | I13: TODO
A14: NC-013 | B14: noun_class_agreement | C14: Abaana abalungi bali ku ssomero. | D14: Abaana ebirungi bali ku ssomero. | E14: The good children are at school. | F14: aba- → ebi- (cl2 → cl8) | H14: high | I14: TODO
A15: NC-014 | B15: noun_class_agreement | C15: Ekikopo ekitono kiri mu ffumbiro. | D15: Ekikopo akatono kiri mu ffumbiro. | E15: The small cup is in the kitchen. | F15: eki- → aka- (cl7 → cl12) | H15: high | I15: TODO
A16: NC-015 | B16: noun_class_agreement | C16: Embwa ennene eri mu luggya. | D16: Embwa omunene eri mu luggya. | E16: The big dog is in the courtyard. | F16: en- → omu- (cl9 → cl1) | H16: high | I16: TODO
A17: NC-016 | B17: noun_class_agreement | C17: Emmotoka empya eri mu luggya. | D17: Emmotoka ekiggya eri mu luggya. | E17: The new car is in the courtyard. | F17: em- (empya) → eki- (cl9 → cl7) | G17: Check -ggya forms: empya / ekiggya. | H17: medium | I17: TODO
A18: NC-017 | B18: noun_class_agreement | C18: Ekitabo ekiggya kiri mu nsawo. | D18: Ekitabo empya kiri mu nsawo. | E18: The new book is in the bag. | F18: eki- → em- (cl7 → cl9) | G18: Check -ggya forms. | H18: medium | I18: TODO
A19: NC-018 | B19: noun_class_agreement | C19: Omukazi omuwanvu ali mu katale. | D19: Omukazi abawanvu ali mu katale. | E19: The tall woman is in the market. | F19: omu- → aba- (cl1 → cl2) | H19: high | I19: TODO
A20: NC-019 | B20: noun_class_agreement | C20: Abakazi abawanvu bali mu katale. | D20: Abakazi omuwanvu bali mu katale. | E20: The tall women are in the market. | F20: aba- → omu- (cl2 → cl1) | H20: high | I20: TODO
A21: NC-020 | B21: noun_class_agreement | C21: Omugga omuwanvu guli mu kyalo. | D21: Omugga ekiwanvu guli mu kyalo. | E21: The long river is in the village. | F21: omu- → eki- (cl3 → cl7) | H21: high | I21: TODO
A22: NC-021 | B22: noun_class_agreement | C22: Ekitabo kyange kiri wano. | D22: Ekitabo wange kiri wano. | E22: My book is here. | F22: kya- → wa- (cl7 → cl1 possessive) | H22: high | I22: TODO
A23: NC-022 | B23: noun_class_agreement | C23: Ebitabo byange biri wano. | D23: Ebitabo kyange biri wano. | E23: My books are here. | F23: bya- → kya- (cl8 → cl7) | H23: high | I23: TODO
A24: NC-023 | B24: noun_class_agreement | C24: Omwana wange ali wano. | D24: Omwana kyange ali wano. | E24: My child is here. | F24: wa- → kya- (cl1 → cl7) | H24: high | I24: TODO
A25: NC-024 | B25: noun_class_agreement | C25: Abaana bange bali wano. | D25: Abaana wange bali wano. | E25: My children are here. | F25: ba- → wa- (cl2 → cl1) | H25: high | I25: TODO
A26: NC-025 | B26: noun_class_agreement | C26: Embwa yange eri wano. | D26: Embwa kyange eri wano. | E26: My dog is here. | F26: ya- → kya- (cl9 → cl7) | H26: high | I26: TODO
A27: NC-026 | B27: noun_class_agreement | C27: Embwa zange ziri wano. | D27: Embwa yange ziri wano. | E27: My dogs are here. | F27: za- → ya- (cl10 → cl9) | G27: embwa is cl9 and cl10; the verb ziri shows that it is plural. | H27: medium | I27: TODO
A28: NC-027 | B28: noun_class_agreement | C28: Omuti gwange guli wano. | D28: Omuti kyange guli wano. | E28: My tree is here. | F28: gwa- → kya- (cl3 → cl7) | H28: high | I28: TODO
A29: NC-028 | B29: noun_class_agreement | C29: Emiti gyange giri wano. | D29: Emiti byange giri wano. | E29: My trees are here. | F29: gya- → bya- (cl4 → cl8) | H29: high | I29: TODO
A30: NC-029 | B30: noun_class_agreement | C30: Olugoye lwange luli wano. | D30: Olugoye kyange luli wano. | E30: My cloth is here. | F30: lwa- → kya- (cl11 → cl7) | H30: high | I30: TODO
A31: NC-030 | B31: noun_class_agreement | C31: Amagi gange gali wano. | D31: Amagi byange gali wano. | E31: My eggs are here. | F31: ga- → bya- (cl6 → cl8) | H31: high | I31: TODO
A32: NC-031 | B32: noun_class_agreement | C32: Eggi lyange liri wano. | D32: Eggi gange liri wano. | E32: My egg is here. | F32: lya- → ga- (cl5 → cl6) | H32: high | I32: TODO
A33: NC-032 | B33: noun_class_agreement | C33: Akambe kange kali wano. | D33: Akambe kyange kali wano. | E33: My knife is here. | F33: ka- → kya- (cl12 → cl7) | H33: high | I33: TODO
A34: NC-033 | B34: noun_class_agreement | C34: Ennyumba yange eri wano. | D34: Ennyumba lyange eri wano. | E34: My house is here. | F34: ya- → lya- (cl9 → cl5) | H34: high | I34: TODO
A35: NC-034 | B35: noun_class_agreement | C35: Emmotoka yaffe eri wano. | D35: Emmotoka kyaffe eri wano. | E35: Our car is here. | F35: ya- → kya- (cl9 → cl7) | H35: high | I35: TODO
A36: NC-035 | B36: noun_class_agreement | C36: Ekibuga kyaffe kinene. | D36: Ekibuga waffe kinene. | E36: Our town is big. | F36: kya- → wa- (cl7 → cl1) | H36: high | I36: TODO
A37: NC-036 | B37: noun_class_agreement | C37: Omuti guno muwanvu. | D37: Omuti kino muwanvu. | E37: This tree is tall. | F37: gu- → ki- (cl3 → cl7 demonstrative) | H37: high | I37: TODO
A38: NC-037 | B38: noun_class_agreement | C38: Emiti gino miwanvu. | D38: Emiti bino miwanvu. | E38: These trees are tall. | F38: gi- → bi- (cl4 → cl8) | H38: high | I38: TODO
A39: NC-038 | B39: noun_class_agreement | C39: Ekitabo kino kirungi. | D39: Ekitabo guno kirungi. | E39: This book is good. | F39: ki- → gu- (cl7 → cl3) | H39: high | I39: TODO
... A47: NC-046 | B47: noun_class_agreement | C47: Akambe kano katono. | D47: Akambe kino katono. | E47: This knife is small. | F47: ka- → ki- (cl12 → cl7) | H47: high | I47: TODO
...

Sheet paragraphs
A1: id | B1: consistent | C1: switched | D1: referent | E1: class_switch | F1: english | G1: note | H1: my_confidence | I1: STATUS | J1: fixed_consistent | K1: fixed_switched | L1: validator_note
A2: PG-001 | B2: Kato yaguze ekitabo ekiggya. Yakisomye mu lunaku lumu. Kati kiri ku mmeeza. | C2: Kato yaguze ekitabo ekiggya. Yakisomye mu lunaku lumu. Kati giri ku mmeeza. | D2: ekitabo | E2: cl7 → cl9 (ki- → gi-) | F2: Kato bought a new book. He read it in one day. Now it is on the table. | H2: high | I2: TODO
A3: PG-002 | B3: Musoke alina embwa ennene. Buli kiro ekuuma ennyumba ye. Abaana bagyagala nnyo. | C3: Musoke alina embwa ennene. Buli kiro ekuuma ennyumba ye. Abaana bakyagala nnyo. | D3: embwa | E3: cl9 → cl7 (-gi- → -ki-) | F3: Musoke has a big dog. Every night it guards his house. The children love it very much. | H3: high | I3: TODO
A4: PG-003 | B4: Mu luggya lwaffe mulimu omuti omunene. Gulina ebibala bingi. Abaana batera okugulinnya. | C4: Mu luggya lwaffe mulimu omuti omunene. Gulina ebibala bingi. Abaana batera okukilinnya. | D4: omuti | E4: cl3 → cl7 (-gu- → -ki-) | F4: In our courtyard there is a big tree. It has many fruits. The children often climb it. | H4: high | I4: TODO
A5: PG-004 | B5: Taata yaguze emmotoka empya. Ya langi enjeru. Buli ku makya agivuga okugenda ku mulimu. | C5: Taata yaguze emmotoka empya. Ya langi enjeru. Buli ku makya akivuga okugenda ku mulimu. | D5: emmotoka | E5: cl9 → cl7 (-gi- → -ki-) | F5: Father bought a new car. It is white. Every morning he drives it to work. | H5: high | I5: TODO
A6: PG-005 | B6: Abaana bazze okuva ku ssomero. Balumwa enjala nnyo. Maama abawadde emmere. | C6: Abaana bazze okuva ku ssomero. Balumwa enjala nnyo. Maama amuwadde emmere. | D6: abaana | E6: cl2 → cl1 (-ba- → -mu-) | F6: The children have come back from school. They are very hungry. Mother has given them food. | H6: high | I6: TODO
A7: PG-006 | B7: Omwana yagudde ku kkubo. Yakaaba nnyo. Nnyina yamusitudde. | C7: Omwana yagudde ku kkubo. Yakaaba nnyo. Nnyina yakisitudde. | D7: omwana | E7: cl1 → cl7 (-mu- → -ki-) | F7: The child fell on the road. He/she cried a lot. His/her mother picked him/her up. | H7: high | I7: TODO
A8: PG-007 | B8: Twagula amazzi mu dduuka. Gaali manyogovu. Twaganywa mangu. | C8: Twagula amazzi mu dduuka. Gaali manyogovu. Twakinywa mangu. | D8: amazzi | E8: cl6 → cl7 (-ga- → -ki-) | F8: We bought water in the shop. It was cold. We drank it quickly. | H8: medium | I8: TODO
A9: PG-008 | B9: Kampala kye kibuga ekikulu kya Uganda. Kirimu abantu bangi. Abagenyi bangi bakyagala. | C9: Kampala kye kibuga ekikulu kya Uganda. Kirimu abantu bangi. Abagenyi bangi bagyagala. | D9: ekibuga | E9: cl7 → cl9 (-ki- → -gi-) | F9: Kampala is the capital city of Uganda. It has many people. Many visitors love it. | H9: high | I9: TODO
A10: PG-009 | B10: Bazadde bange bazimbye ennyumba empya. Erina ebisenge bina. Buli muntu agyagala. | C10: Bazadde bange bazimbye ennyumba empya. Erina ebisenge bina. Buli muntu akyagala. | D10: ennyumba | E10: cl9 → cl7 (-gi- → -ki-) | F10: My parents have built a new house. It has four rooms. Everybody likes it. | H10: high | I10: TODO
A11: PG-010 | B11: Nnaguze olugoye olulungi. Lwa langi emmyufu. Nja kulwambala ku Ssande. | C11: Nnaguze olugoye olulungi. Lwa langi emmyufu. Nja kukyambala ku Ssande. | D11: olugoye | E11: cl11 → cl7 (-lu- → -ki-) | F11: I bought a nice cloth. It is red. I will wear it on Sunday. | H11: medium | I11: TODO
A12: PG-011 | B12: Taata yasimbye emiti mingi. Kati giwanvu nnyo. Tugifukirira buli lunaku. | C12: Taata yasimbye emiti mingi. Kati giwanvu nnyo. Tugufukirira buli lunaku. | D12: emiti | E12: cl4 → cl3 (-gi- → -gu-) | F12: Father planted many trees. Now they are very tall. We water them every day. | H12: high | I12: TODO
A13: PG-012 | B13: Omusomesa yatuwadde ebitabo bisatu. Biwandiikiddwa mu Luganda. Tubisoma buli lunaku. | C13: Omusomesa yatuwadde ebitabo bisatu. Biwandiikiddwa mu Luganda. Tukisoma buli lunaku. | D13: ebitabo | E13: cl8 → cl7 (-bi- → -ki-) | F13: The teacher gave us three books. They are written in Luganda. We read them every day. | H13: high | I13: TODO
A14: PG-013 | B14: Maama alina akambe akasongovu. Kasala bulungi nnyo. Akakozesa okusala enva. | C14: Maama alina akambe akasongovu. Kasala bulungi nnyo. Akikozesa okusala enva. | D14: akambe | E14: cl12 → cl7 (-ka- → -ki-) | F14: Mother has a sharp knife. It cuts very well. She uses it to cut vegetables. | H14: medium | I14: TODO
A15: PG-014 | B15: Jjajja alina ente nnyingi. Zirya omuddo mu nnimiro. Buli kawungeezi azikomyawo eka. | C15: Jjajja alina ente nnyingi. Zirya omuddo mu nnimiro. Buli kawungeezi agikomyawo eka. | D15: ente (plural) | E15: cl10 → cl9 (-zi- → -gi-) | F15: Grandparent has many cows. They eat grass in the field. Every evening he/she brings them home. | G15: This switch changes number (plural → singular) in the same noun class pair. | H15: medium | I15: TODO
A16: PG-015 | B16: Mu kyalo kyaffe mulimu omugga omunene. Gukulukuta okuva ku lusozi. Abantu bagukozesa okunaaba. | C16: Mu kyalo kyaffe mulimu omugga omunene. Gukulukuta okuva ku lusozi. Abantu bakikozesa okunaaba. | D16: omugga | E16: cl3 → cl7 (-gu- → -ki-) | F16: In our village there is a big river. It flows from the hill. People use it for bathing. | H16: medium | I16: TODO
A17: PG-016 | B17: Nnaguze amagi kkumi mu katale. Gaali mapya. Maama yagafumbye ku makya. | C17: Nnaguze amagi kkumi mu katale. Gaali mapya. Maama yagifumbye ku makya. | D17: amagi | E17: cl6 → cl9 (-ga- → -gi-) | F17: I bought ten eggs in the market. They were fresh. Mother cooked them in the morning. | H17: medium | I17: TODO
A18: PG-017 | B18: Ku kkubo waliwo ejjinja eddene. Lizibye ekkubo. Abasajja balisitudde. | C18: Ku kkubo waliwo ejjinja eddene. Lizibye ekkubo. Abasajja bakisitudde. | D18: ejjinja | E18: cl5 → cl7 (-li- → -ki-) | F18: On the road there is a big stone. It has blocked the road. The men have lifted it. | G18: balisitudde could also be read as a future form; check. | H18: low | I18: TODO
A19: PG-018 | B19: Omwana yamenye ekikopo. Kyali kya maama. Kati kiri mu bitundu bibiri. | C19: Omwana yamenye ekikopo. Kyali kya maama. Kati guli mu bitundu bibiri. | D19: ekikopo | E19: cl7 → cl3 (ki- → gu-) | F19: The child broke the cup. It was mother's. Now it is in two pieces. | H19: high | I19: TODO
A20: PG-019 | B20: Abagenyi batuuse ku ssaawa ttaano. Baali bakooye nnyo. Twabawadde amazzi okunywa. | C20: Abagenyi batuuse ku ssaawa ttaano. Baali bakooye nnyo. Twamuwadde amazzi okunywa. | D20: abagenyi | E20: cl2 → cl1 (-ba- → -mu-) | F20: The guests arrived at eleven o'clock. They were very tired. We gave them water to drink. | H20: high | I20: TODO
A21: PG-020 | B21: Kizza yaguze embuzi mu katale. Erina amaaso amaddugavu. Agisibye wansi w'omuti. | C21: Kizza yaguze embuzi mu katale. Erina amaaso amaddugavu. Akisibye wansi w'omuti. | D21: embuzi | E21: cl9 → cl7 (-gi- → -ki-) | F21: Kizza bought a goat in the market. It has black eyes. He has tied it under a tree. | H21: high | I21: TODO
A22: PG-021 | B22: Abaana baguze omupiira omuggya. Gwa langi ya kyenvu. Bagusambye olunaku lwonna. | C22: Abaana baguze omupiira omuggya. Gwa langi ya kyenvu. Bakisambye olunaku lwonna. | D22: omupiira | E22: cl3 → cl7 (-gu- → -ki-) | F22: The children bought a new ball. It is yellow. They have kicked it all day. | H22: medium | I22: TODO
A23: PG-022 | B23: Essomero lyaffe liri ku lusozi. Lirina abayizi bangi. Lyatandika emyaka mingi emabega. | C23: Essomero lyaffe liri ku lusozi. Lirina abayizi bangi. Kyatandika emyaka mingi emabega. | D23: essomero | E23: cl5 → cl7 (lya- → kya-) | F23: Our school is on the hill. It has many students. It started many years ago. | H23: medium | I23: TODO
A24: PG-023 | B24: Ku mugga waliwo olutindo oluggya. Luzimbiddwa mu kyuma. Abantu bangi baluyitako buli lunaku. | C24: Ku mugga waliwo olutindo oluggya. Luzimbiddwa mu kyuma. Abantu bangi bakiyitako buli lunaku. | D24: olutindo | E24: cl11 → cl7 (-lu- → -ki-) | F24: On the river there is a new bridge. It is built of iron. Many people cross it every day. | H24: medium | I24: TODO
A25: PG-024 | B25: Nnalabye ekinyonyi ekirungi ku muti. Kyali kya langi ya bbululu. Kyabuuse mangu ddala. | C25: Nnalabye ekinyonyi ekirungi ku muti. Kyali kya langi ya bbululu. Gwabuuse mangu ddala. | D25: ekinyonyi | E25: cl7 → cl3 (kya- → gwa-) | F25: I saw a beautiful bird on a tree. It was blue. It flew away very quickly. | H25: medium | I25: TODO
A26: PG-025 | B26: Maama yafumbye amatooke. Gaali gawooma nnyo. Twagalidde ku kyeggulo. | C26: Maama yafumbye amatooke. Gaali gawooma nnyo. Twakiridde ku kyeggulo. | D26: amatooke | E26: cl6 → cl7 (-ga- → -ki-) | F26: Mother cooked matooke. It was very tasty. We ate it at supper. | H26: medium | I26: TODO
A27: PG-026 | B27: Nnafunye ebbaluwa okuva ewa mukwano gwange. Yali mpanvu nnyo. Nnagisomye emirundi ebiri. | C27: Nnafunye ebbaluwa okuva ewa mukwano gwange. Yali mpanvu nnyo. Nnakisomye emirundi ebiri. | D27: ebbaluwa | E27: cl9 → cl7 (-gi- → -ki-) | F27: I received a letter from my friend. It was very long. I read it two times. | H27: high | I27: TODO
A28: PG-027 | B28: Abayizi bayize oluyimba oluggya. Lunyuma nnyo. Baluyimba buli ku makya. | C28: Abayizi bayize oluyimba oluggya. Lunyuma nnyo. Bakiyimba buli ku makya. | D28: oluyimba | E28: cl11 → cl7 (-lu- → -ki-) | F28: The students have learned a new song. It is very nice. They sing it every morning. | H28: medium | I28: TODO
A29: PG-028 | B29: Jjajja abeera mu kyalo ekitono. Kiri wala okuva e Kampala. Tukikyalira buli Ssekukkulu. | C29: Jjajja abeera mu kyalo ekitono. Kiri wala okuva e Kampala. Tugukyalira buli Ssekukkulu. | D29: ekyalo | E29: cl7 → cl3 (-ki- → -gu-) | F29: Grandparent lives in a small village. It is far from Kampala. We visit it every Christmas. | H29: medium | I29: TODO
A30: PG-029 | B30: Omusomesa waffe mulungi nnyo. Atusomesa okubala. Abayizi bonna bamwagala. | C30: Omusomesa waffe mulungi nnyo. Atusomesa okubala. Abayizi bonna bakyagala. | D30: omusomesa | E30: cl1 → cl7 (-mu- → -ki-) | F30: Our teacher is very good. He/she teaches us mathematics. All the students love him/her. | H30: high | I30: TODO
A31: PG-030 | B31: Maama yafumbye emmere nnyingi. Yali ewooma nnyo. Abagenyi bonna baagiridde. | C31: Maama yafumbye emmere nnyingi. Yali ewooma nnyo. Abagenyi bonna baakiridde. | D31: emmere | E31: cl9 → cl7 (-gi- → -ki-) | F31: Mother cooked a lot of food. It was very tasty. All the guests ate it. | H31: medium | I31: TODO

Sheet variation
A1: id | B1: form_a | C1: form_b | D1: english | E1: variation_type | F1: note | G1: my_confidence | H1: STATUS | I1: fixed_form_a | J1: fixed_form_b | K1: validator_note
A2: VA-001 | B2: Nze ŋŋenda ku ssomero. | C2: Nze ngenda ku ssomero. | D2: I am going to school. | E2: spelling (ŋŋ / ng) | G2: high | H2: TODO
A3: VA-002 | B3: Weebale nnyo. | C3: Webale nnyo. | D3: Thank you very much. | E3: spelling (ee / e) | G3: high | H3: TODO
A4: VA-003 | B4: Maama agenda mu katale. | C4: Maama bagenda mu katale. | D4: Mother is going to the market. | E4: honorific plural | G4: high | H4: TODO
A5: VA-004 | B5: Nja kugenda e Kampala. | C5: Nnaagenda e Kampala. | D5: I will go to Kampala. | E5: future form (ja ku- / -naa-) | G5: high | H5: TODO
A6: VA-005 | B6: Ennyumba yange nnene. | C6: Enju yange nnene. | D6: My house is big. | E6: synonym (ennyumba / enju) | G6: high | H6: TODO
A7: VA-006 | B7: Tewali kizibu. | C7: Tewali buzibu. | D7: There is no problem. | E7: noun class of the noun (ki- / bu-) | G7: medium | H7: TODO
A8: VA-007 | B8: Simanyi. | C8: Sikimanyi. | D8: I do not know. | E8: optional object marker | G8: medium | H8: TODO
A9: VA-008 | B9: Atuuse. | C9: Yatuuse. | D9: He/she has arrived. | E9: perfect / recent past | G9: medium | H9: TODO
A10: VA-009 | B10: Nnalaba omwana. | C10: Omwana nnamulaba. | D10: I saw the child. | E10: word order with object marker | G10: high | H10: TODO
A11: VA-010 | B11: Kale. | C11: Kaale. | D11: Okay. | E11: spelling (a / aa) | G11: medium | H11: TODO
A12: VA-011 | B12: Nnina ssente. | C12: Nnina sente. | D12: I have money. | E12: spelling (ss / s) | G12: high | H12: TODO
A13: VA-012 | B13: Ali e Kampala. | C13: Ali mu Kampala. | D13: He/she is in Kampala. | E13: locative (e / mu) | G13: medium | H13: TODO
A14: VA-013 | B14: Jjajja ajja enkya. | C14: Jjajja bajja enkya. | D14: Grandparent is coming tomorrow. | E14: honorific plural | G14: high | H14: TODO
A15: VA-014 | B15: Omusajja gwe nnalaba yagenda. | C15: Omusajja nnalaba yagenda. | D15: The man that I saw went away. | E15: optional relative pronoun | F15: Not sure that the short form is accepted. | G15: low | H15: TODO
A16: VA-015 | B16: Yali agenda. | C16: Yali ng'agenda. | D16: He/she was going. | E16: progressive form | G16: medium | H16: TODO
A17: VA-016 | B17: Webale okujja. | C17: Webale kujja. | D17: Thank you for coming. | E17: optional augment on the infinitive | G17: medium | H17: TODO
A18: VA-017 | B18: Weebale ssebo. | C18: Weebale sebo. | D18: Thank you, sir. | E18: spelling (ss / s) | G18: high | H18: TODO
A19: VA-018 | B19: Leero enkuba etonnya. | C19: Enkuba etonnya leero. | D19: Today it is raining. | E19: word order | G19: high | H19: TODO
A20: VA-019 | B20: Nnyabo, weebale. | C20: Nyabo, weebale. | D20: Madam, thank you. | E20: spelling (nny / ny) | G20: high | H20: TODO
A21: VA-020 | B21: Taata yagenze ku mulimu. | C21: Taata baagenze ku mulimu. | D21: Father has gone to work. | E21: honorific plural | G21: high | H21: TODO

Sheet progress
A1: sheet / error type | B1: total | C1: TODO | D1: OK | E1: FIXED | F1: DROP | G1: usable (OK + FIXED)
A2: minimal_pairs: noun_class_agreement | B2: =COUNTIFS(minimal_pairs!$B$2:$B$201,"noun_class_agreement") -> 50 | C2: =COUNTIFS(minimal_pairs!$B$2:$B$201,"noun_class_agreement",minimal_pairs!$I$2:$I$201,"TODO") -> 50 | D2: =COUNTIFS(minimal_pairs!$B$2:$B$201,"noun_class_agreement",minimal_pairs!$I$2:$I$201,"OK") -> 0 | E2: =COUNTIFS(minimal_pairs!$B$2:$B$201,"noun_class_agreement",minimal_pairs!$I$2:$I$201,"FIXED") -> 0 | F2: =COUNTIFS(minimal_pairs!$B$2:$B$201,"noun_class_agreement",minimal_pairs!$I$2:$I$201,"DROP") -> 0 | G2: =D2+E2 -> 0
A3: minimal_pairs: subject_object_marker | B3: =COUNTIFS(minimal_pairs!$B$2:$B$201,"subject_object_marker") -> 50 | C3: =COUNTIFS(minimal_pairs!$B$2:$B$201,"subject_object_marker",minimal_pairs!$I$2:$I$201,"TODO") -> 50 | D3: =COUNTIFS(minimal_pairs!$B$2:$B$201,"subject_object_marker",minimal_pairs!$I$2:$I$201,"OK") -> 0 | E3: =COUNTIFS(minimal_pairs!$B$2:$B$201,"subject_object_marker",minimal_pairs!$I$2:$I$201,"FIXED") -> 0 | F3: =COUNTIFS(minimal_pairs!$B$2:$B$201,"subject_object_marker",minimal_pairs!$I$2:$I$201,"DROP") -> 0 | G3: =D3+E3 -> 0
A4: minimal_pairs: tense_aspect | B4: =COUNTIFS(minimal_pairs!$B$2:$B$201,"tense_aspect") -> 50 | C4: =COUNTIFS(minimal_pairs!$B$2:$B$201,"tense_aspect",minimal_pairs!$I$2:$I$201,"TODO") -> 50 | D4: =COUNTIFS(minimal_pairs!$B$2:$B$201,"tense_aspect",minimal_pairs!$I$2:$I$201,"OK") -> 0 | E4: =COUNTIFS(minimal_pairs!$B$2:$B$201,"tense_aspect",minimal_pairs!$I$2:$I$201,"FIXED") -> 0 | F4: =COUNTIFS(minimal_pairs!$B$2:$B$201,"tense_aspect",minimal_pairs!$I$2:$I$201,"DROP") -> 0 | G4: =D4+E4 -> 0
A5: minimal_pairs: negation | B5: =COUNTIFS(minimal_pairs!$B$2:$B$201,"negation") -> 50 | C5: =COUNTIFS(minimal_pairs!$B$2:$B$201,"negation",minimal_pairs!$I$2:$I$201,"TODO") -> 50 | D5: =COUNTIFS(minimal_pairs!$B$2:$B$201,"negation",minimal_pairs!$I$2:$I$201,"OK") -> 0 | E5: =COUNTIFS(minimal_pairs!$B$2:$B$201,"negation",minimal_pairs!$I$2:$I$201,"FIXED") -> 0 | F5: =COUNTIFS(minimal_pairs!$B$2:$B$201,"negation",minimal_pairs!$I$2:$I$201,"DROP") -> 0 | G5: =D5+E5 -> 0
A6: paragraphs | B6: =COUNTA(paragraphs!$A$2:$A$31) -> 30 | C6: =COUNTIF(paragraphs!$I$2:$I$31,"TODO") -> 30 | D6: =COUNTIF(paragraphs!$I$2:$I$31,"OK") -> 0 | E6: =COUNTIF(paragraphs!$I$2:$I$31,"FIXED") -> 0 | F6: =COUNTIF(paragraphs!$I$2:$I$31,"DROP") -> 0 | G6: =D6+E6 -> 0
A7: variation | B7: =COUNTA(variation!$A$2:$A$21) -> 20 | C7: =COUNTIF(variation!$H$2:$H$21,"TODO") -> 20 | D7: =COUNTIF(variation!$H$2:$H$21,"OK") -> 0 | E7: =COUNTIF(variation!$H$2:$H$21,"FIXED") -> 0 | F7: =COUNTIF(variation!$H$2:$H$21,"DROP") -> 0 | G7: =D7+E7 -> 0
A8: all | B8: =SUM(B2:B7) -> 250 | C8: =SUM(C2:C7) -> 250 | D8: =SUM(D2:D7) -> 0 | E8: =SUM(E2:E7) -> 0 | F8: =SUM(F2:F7) -> 0 | G8: =SUM(G2:G7) -> 0
